<?xml version="1.0" ?>
<!-- =================================================================================== -->
<!-- |    This document was autogenerated by xacro from rb1_500es_u.urdf.xacro         | -->
<!-- |    EDITING THIS FILE BY HAND IS NOT RECOMMENDED                                 | -->
<!-- =================================================================================== -->
<robot name="rb1_500es_u">
  <link name="link0">
    <visual>
      <geometry>
        <mesh filename="package://rbpodo_description/meshes/rb1_500es_u/visual/link0.dae"/>
      </geometry>
    </visual>
    <collision>
      <geometry>
        <mesh filename="package://rbpodo_description/meshes/rb1_500es_u/collision/link0.stl"/>
      </geometry>
    </collision>
  </link>
  <link name="link1">
    <visual>
      <geometry>
        <mesh filename="package://rbpodo_description/meshes/rb1_500es_u/visual/link1.dae"/>
      </geometry>
    </visual>
    <collision>
      <geometry>
        <mesh filename="package://rbpodo_description/meshes/rb1_500es_u/collision/link1.stl"/>
      </geometry>
    </collision>
    <inertial>
      <origin rpy="0 0 0" xyz="-0.00002208 -0.02981214 -0.00332683"/>
      <mass value="1.23358625"/>
      <inertia ixx="0.00138438" ixy="3e-08" ixz="8.1e-07" iyy="0.00107381" iyz="0.00011138" izz="0.00128285"/>
    </inertial>
  </link>
  <link name="link2">
    <visual>
      <geometry>
        <mesh filename="package://rbpodo_description/meshes/rb1_500es_u/visual/link2.dae"/>
      </geometry>
    </visual>
    <collision>
      <geometry>
        <mesh filename="package://rbpodo_description/meshes/rb1_500es_u/collision/link2.stl"/>
      </geometry>
    </collision>
    <inertial>
      <origin rpy="0 0 0" xyz="0.00006274 -0.08257860 0.13384551"/>
      <mass value="1.08410838"/>
      <inertia ixx="0.00577018" ixy="2.73e-06" ixz="-1.7e-07" iyy="0.00539708" iyz="-0.00055405" izz="0.00089785"/>
    </inertial>
  </link>
  <link name="link3">
    <visual>
      <geometry>
        <mesh filename="package://rbpodo_description/meshes/rb1_500es_u/visual/link3.dae"/>
      </geometry>
    </visual>
    <collision>
      <geometry>
        <mesh filename="package://rbpodo_description/meshes/rb1_500es_u/collision/link3.stl"/>
      </geometry>
    </collision>
    <inertial>
      <origin rpy="0 0 0" xyz="-0.00008419 -0.00101844 0.02015049"/>
      <mass value="0.66596275"/>
      <inertia ixx="0.00058233" ixy="4.3e-07" ixz="-2.66e-06" iyy="0.00056656" iyz="-1.299e-05" izz="0.0003224"/>
    </inertial>
  </link>
  <link name="link4">
    <visual>
      <geometry>
        <mesh filename="package://rbpodo_description/meshes/rb1_500es_u/visual/link4.dae"/>
      </geometry>
    </visual>
    <collision>
      <geometry>
        <mesh filename="package://rbpodo_description/meshes/rb1_500es_u/collision/link4.stl"/>
      </geometry>
    </collision>
    <inertial>
      <origin rpy="0 0 0" xyz="0.00008446 -0.06824336 0.18891470"/>
      <mass value="0.98411887"/>
      <inertia ixx="0.0037364" ixy="2.53e-06" ixz="-2.5e-07" iyy="0.00284239" iyz="0.00093" izz="0.00133647"/>
    </inertial>
  </link>
  <link name="link5">
    <visual>
      <geometry>
        <mesh filename="package://rbpodo_description/meshes/rb1_500es_u/visual/link5.dae"/>
      </geometry>
    </visual>
    <collision>
      <geometry>
        <mesh filename="package://rbpodo_description/meshes/rb1_500es_u/collision/link5.stl"/>
      </geometry>
    </collision>
    <inertial>
      <origin rpy="0 0 0" xyz="-0.00008419 -0.00101844 0.02015049"/>
      <mass value="0.66596275"/>
      <inertia ixx="0.00058233" ixy="4.3e-07" ixz="-2.66e-06" iyy="0.00056656" iyz="-1.299e-05" izz="0.0003224"/>
    </inertial>
  </link>
  <link name="link6">
    <visual>
      <geometry>
        <mesh filename="package://rbpodo_description/meshes/rb1_500es_u/visual/link6.dae"/>
      </geometry>
    </visual>
    <collision>
      <geometry>
        <mesh filename="package://rbpodo_description/meshes/rb1_500es_u/collision/link6.stl"/>
      </geometry>
    </collision>
    <inertial>
      <origin rpy="0 0 0" xyz="-0.001 -0.001 0.068"/>
      <mass value="0.211"/>
      <inertia ixx="0.00050752" ixy="0.0001055" ixz="3.1e-07" iyy="0.00030773" iyz="-3e-07" izz="0.00072315"/>
    </inertial>
  </link>
  <link name="tcp"/>
  <joint name="base" type="revolute">
    <origin rpy="0 0 0" xyz="0 0 0.1568"/>
    <parent link="link0"/>
    <child link="link1"/>
    <axis xyz="0 0 1"/>
    <limit effort="10" lower="-3.14" upper="3.14" velocity="3.14"/>
  </joint>
  <joint name="shoulder" type="revolute">
    <origin rpy="0 0 0" xyz="0 0 0"/>
    <parent link="link1"/>
    <child link="link2"/>
    <axis xyz="0 1 0"/>
    <limit effort="10" lower="-3.14" upper="3.14" velocity="3.14"/>
  </joint>
  <joint name="elbow" type="revolute">
    <origin rpy="0 0 0" xyz="0 0 0.1800"/>
    <parent link="link2"/>
    <child link="link3"/>
    <axis xyz="0 1 0"/>
    <limit effort="10" lower="-3.14" upper="3.14" velocity="3.14"/>
  </joint>
  <joint name="wrist1" type="revolute">
    <origin rpy="0 0 0" xyz="0 0 0"/>
    <parent link="link3"/>
    <child link="link4"/>
    <axis xyz="0 0 1"/>
    <limit effort="10" lower="-3.14" upper="3.14" velocity="3.14"/>
  </joint>
  <joint name="wrist2" type="revolute">
    <origin rpy="0 0 0" xyz="0 0 0.2198"/>
    <parent link="link4"/>
    <child link="link5"/>
    <axis xyz="0 1 0"/>
    <limit effort="10" lower="-3.14" upper="3.14" velocity="3.14"/>
  </joint>
  <joint name="wrist3" type="revolute">
    <origin rpy="0 0 0" xyz="0 0 0"/>
    <parent link="link5"/>
    <child link="link6"/>
    <axis xyz="0 0 1"/>
    <limit effort="10" lower="-3.14" upper="3.14" velocity="3.14"/>
  </joint>
  <joint name="tcp_joint" type="fixed">
    <origin rpy="0 0 0" xyz="0 0 0.1"/>
    <parent link="link6"/>
    <child link="tcp"/>
  </joint>
  <ros2_control name="RBPodoHardwareInterface" type="system">
    <hardware>
      <plugin>rbpodo_hardware/RBPodoHardwareInterface</plugin>
      <param name="cb_simulation">True</param>
      <param name="robot_ip">10.0.2.7</param>
    </hardware>
    <joint name="base">
      <param name="initial_position">0.0</param>
      <param name="torque_constant">10.100000000000001</param>
      <command_interface name="effort"/>
      <command_interface name="velocity"/>
      <command_interface name="position"/>
      <state_interface name="position"/>
      <state_interface name="effort"/>
    </joint>
    <joint name="shoulder">
      <param name="initial_position">0.0</param>
      <param name="torque_constant">10.100000000000001</param>
      <command_interface name="effort"/>
      <command_interface name="velocity"/>
      <command_interface name="position"/>
      <state_interface name="position"/>
      <state_interface name="effort"/>
    </joint>
    <joint name="elbow">
      <param name="initial_position">0.0</param>
      <param name="torque_constant">10.100000000000001</param>
      <command_interface name="effort"/>
      <command_interface name="velocity"/>
      <command_interface name="position"/>
      <state_interface name="position"/>
      <state_interface name="effort"/>
    </joint>
    <joint name="wrist1">
      <param name="initial_position">0.0</param>
      <param name="torque_constant">10.100000000000001</param>
      <command_interface name="effort"/>
      <command_interface name="velocity"/>
      <command_interface name="position"/>
      <state_interface name="position"/>
      <state_interface name="effort"/>
    </joint>
    <joint name="wrist2">
      <param name="initial_position">0.0</param>
      <param name="torque_constant">5.5</param>
      <command_interface name="effort"/>
      <command_interface name="velocity"/>
      <command_interface name="position"/>
      <state_interface name="position"/>
      <state_interface name="effort"/>
    </joint>
    <joint name="wrist3">
      <param name="initial_position">0.0</param>
      <param name="torque_constant">5.5</param>
      <command_interface name="effort"/>
      <command_interface name="velocity"/>
      <command_interface name="position"/>
      <state_interface name="position"/>
      <state_interface name="effort"/>
    </joint>
  </ros2_control>
</robot>
